[08/20/2022 - 06:04:55] File "Devign/main.py", line 68  	Reading already processed data from data/MSR/full_experiment_real_data_processed/processed.bin!	
Traceback (most recent call last):
  File "Devign/main.py", line 84, in <module>
    splits_reveal = dataset.load_splits(all_src, os.path.join(splits_dir, 'splits.csv'))
  File "/home/<ANONYMOUS>/code/ReVeal/Devign/data_loader/dataset.py", line 63, in load_splits
    splits_df = pd.read_csv(splits_src)
  File "/home/<ANONYMOUS>/.local/lib/python3.8/site-packages/pandas/util/_decorators.py", line 311, in wrapper
    return func(*args, **kwargs)
  File "/home/<ANONYMOUS>/.local/lib/python3.8/site-packages/pandas/io/parsers/readers.py", line 680, in read_csv
    return _read(filepath_or_buffer, kwds)
  File "/home/<ANONYMOUS>/.local/lib/python3.8/site-packages/pandas/io/parsers/readers.py", line 575, in _read
    parser = TextFileReader(filepath_or_buffer, **kwds)
  File "/home/<ANONYMOUS>/.local/lib/python3.8/site-packages/pandas/io/parsers/readers.py", line 934, in __init__
    self._engine = self._make_engine(f, self.engine)
  File "/home/<ANONYMOUS>/.local/lib/python3.8/site-packages/pandas/io/parsers/readers.py", line 1218, in _make_engine
    self.handles = get_handle(  # type: ignore[call-overload]
  File "/home/<ANONYMOUS>/.local/lib/python3.8/site-packages/pandas/io/common.py", line 786, in get_handle
    handle = open(
FileNotFoundError: [Errno 2] No such file or directory: 'data/MSR/full_experiment_real_data_processed/vbugtype_bugtype_input_validation/splits.csv'
