cuda: True
Traceback (most recent call last):
  File "Vuld_SySe/representation_learning/api_test.py", line 47, in <module>
    assert os.path.exists(ds), ds
AssertionError: data/MSR/full_experiment_real_data_processed/vbugtype_bugtype_privilege_escalation_authorization
